2018-04-24 15:37:01.183 - pyansibleinv -        dbbackup_mysql_disable -  INFO - args:{'--cluster_id': None,
 '--data_host': 'dcs-db-c00aee9f.iad1:10.41.234.57',
 '--day': '*',
 '--day_of_week': None,
 '--dbfqdn': 'dcs-db-c00aee9f.iad1',
 '--dbtype': 'mysql',
 '--hour': '23',
 '--isets': '2',
 '--minute': '2',
 '--month': '*',
 '--rsets': '3',
 '--ssh_try_limit': '600',
 '--sshkey': '/opt/ansible/db.pem',
 '--sshpass': 'LR1!Ika',
 '--taskid': None,
 '--template_only': False,
 '--workdir': '/opt/ansible',
 'dbbackup': True,
 'debug': False,
 'disable': True,
 'enable': False,
 'list': False,
 'status': False}
2018-04-24 15:37:01.183 - pyansibleinv -        dbbackup_mysql_disable -  INFO - dict:{'template_only': False, 'rsets': '3', 'month': '*', 'cluster_id': None, 'data_host': 'dcs-db-c00aee9f.iad1:10.41.234.57', 'sshkey': '/opt/ansible/db.pem', 'atus': False, 'dbtype': 'mysql', 'able': False, 'day': '*', 'taskid': None, 'dbfqdn': 'dcs-db-c00aee9f.iad1', 'workdir': '/opt/ansible', 'sable': True, 'sshpass': 'LR1!Ika', 'bug': False, 'minute': '2', 'uuid': '7e535817-a5f2-47af-b17d-5340315aba35', 'ssh_try_limit': '600', 'task_id': '  external_task_id: 7e535817-a5f2-47af-b17d-5340315aba35\n', 'hour': '23', 'day_of_week': None, 'st': False, 'backup': True, 'isets': '2'}
2018-04-24 15:37:01.184 - pyansibleinv -        dbbackup_mysql_disable -  INFO - create ansible hosts: /opt/ansible/inventory/7e535817-a5f2-47af-b17d-5340315aba35/hosts
2018-04-24 15:37:01.184 - pyansibleinv -        dbbackup_mysql_disable -  INFO - craete ansible playbooks: /opt/ansible/dbbackup_mysql_disable_7e535817-a5f2-47af-b17d-5340315aba35.yml
2018-04-24 15:37:01.196 - pyansibleinv -        dbbackup_mysql_disable -  INFO - check ssh availability
2018-04-24 15:37:01.196 - pyansibleinv - dbbackup_mysql_disable_stdout -  INFO - Attempting to connect to 10.41.234.57 on port 22
2018-04-24 15:37:01.264 - pyansibleinv - dbbackup_mysql_disable_stdout -  INFO - Connected to 10.41.234.57 on port 22
2018-04-24 15:37:01.265 - pyansibleinv - dbbackup_mysql_disable_stdout -  INFO - Attempting to connect to 10.41.234.57 on port 22
2018-04-24 15:37:01.332 - pyansibleinv - dbbackup_mysql_disable_stdout -  INFO - Connected to 10.41.234.57 on port 22
2018-04-24 15:37:01.333 - pyansibleinv -        dbbackup_mysql_disable -  INFO - run ansible from python
2018-04-24 15:37:01.952 - pyansibleinv - dbbackup_mysql_disable_stdout -  INFO - 
2018-04-24 15:37:01.952 - pyansibleinv - dbbackup_mysql_disable_stdout -  INFO - PLAY [crontab] ********************************************************************************************************************************************************************************
2018-04-24 15:37:02.705 - pyansibleinv - dbbackup_mysql_disable_stdout -  INFO - 
2018-04-24 15:37:02.705 - pyansibleinv - dbbackup_mysql_disable_stdout -  INFO - TASK [set crontab] ****************************************************************************************************************************************************************************
2018-04-24 15:37:05.451 - pyansibleinv - dbbackup_mysql_disable_stdout -  INFO - [0;32mok: [dcs-db-c00aee9f.iad1][0m
2018-04-24 15:37:06.167 - pyansibleinv - dbbackup_mysql_disable_stdout -  INFO - 
2018-04-24 15:37:06.167 - pyansibleinv - dbbackup_mysql_disable_stdout -  INFO - TASK [query crontab] **************************************************************************************************************************************************************************
2018-04-24 15:37:08.158 - pyansibleinv - dbbackup_mysql_disable_stdout -  INFO - [0;32mok: [dcs-db-c00aee9f.iad1][0m
2018-04-24 15:37:08.867 - pyansibleinv - dbbackup_mysql_disable_stdout -  INFO - 
2018-04-24 15:37:08.867 - pyansibleinv - dbbackup_mysql_disable_stdout -  INFO - TASK [Record crontab result] ******************************************************************************************************************************************************************
2018-04-24 15:37:08.958 - pyansibleinv - dbbackup_mysql_disable_stdout -  INFO - [0;31mfatal: [dcs-db-c00aee9f.iad1]: FAILED! => {"changed": false, "msg": "Parameter 'value' is required"}[0m
2018-04-24 15:37:08.981 - pyansibleinv - dbbackup_mysql_disable_stdout -  INFO - 	to retry, use: --limit @/opt/ansible/dbbackup_mysql_disable_7e535817-a5f2-47af-b17d-5340315aba35.retry
2018-04-24 15:37:08.982 - pyansibleinv - dbbackup_mysql_disable_stdout -  INFO - 
2018-04-24 15:37:08.982 - pyansibleinv - dbbackup_mysql_disable_stdout -  INFO - PLAY RECAP ************************************************************************************************************************************************************************************
2018-04-24 15:37:08.982 - pyansibleinv - dbbackup_mysql_disable_stdout -  INFO - [0;31mdcs-db-c00aee9f.iad1[0m       : [0;32mok=2   [0m changed=0    unreachable=0    [0;31mfailed=1   [0m
2018-04-24 15:37:09.016 - pyansibleinv - dbbackup_mysql_disable_stdout -  INFO - --- Total Excution time: 0:00:07.833159 ---
2018-04-24 15:37:09.052 - pyansibleinv - dbbackup_mysql_disable_stderr - ERROR - No handlers could be found for logger "pyansibleinv"
2018-04-24 15:37:09.052 - pyansibleinv - dbbackup_mysql_disable_stderr - ERROR - Traceback (most recent call last):
2018-04-24 15:37:09.052 - pyansibleinv - dbbackup_mysql_disable_stderr - ERROR -   File "/usr/bin/pyansibleinv", line 11, in <module>
2018-04-24 15:37:09.053 - pyansibleinv - dbbackup_mysql_disable_stderr - ERROR - load_entry_point('pyansibleinv==0.1.0', 'console_scripts', 'pyansibleinv')()
2018-04-24 15:37:09.053 - pyansibleinv - dbbackup_mysql_disable_stderr - ERROR -   File "/usr/lib/python2.7/site-packages/pyansibleinv/pyansibleinv.py", line 34, in main
2018-04-24 15:37:09.053 - pyansibleinv - dbbackup_mysql_disable_stderr - ERROR - return getattr(module_script, func)(module_args)
2018-04-24 15:37:09.053 - pyansibleinv - dbbackup_mysql_disable_stderr - ERROR -   File "/usr/lib/python2.7/site-packages/pyansibleinv/inv_module/dbbackup.py", line 151, in disable
2018-04-24 15:37:09.053 - pyansibleinv - dbbackup_mysql_disable_stderr - ERROR - return json.dumps(dbbackup(args, 'disable', fields))
2018-04-24 15:37:09.053 - pyansibleinv - dbbackup_mysql_disable_stderr - ERROR -   File "/usr/lib/python2.7/site-packages/pyansibleinv/inv_module/dbbackup.py", line 112, in dbbackup
2018-04-24 15:37:09.054 - pyansibleinv - dbbackup_mysql_disable_stderr - ERROR - tmp_dict = json.loads(result['stdout'])['Value']
2018-04-24 15:37:09.054 - pyansibleinv - dbbackup_mysql_disable_stderr - ERROR -   File "/usr/lib64/python2.7/json/__init__.py", line 338, in loads
2018-04-24 15:37:09.063 - pyansibleinv - dbbackup_mysql_disable_stderr - ERROR - return _default_decoder.decode(s)
2018-04-24 15:37:09.064 - pyansibleinv - dbbackup_mysql_disable_stderr - ERROR -   File "/usr/lib64/python2.7/json/decoder.py", line 366, in decode
2018-04-24 15:37:09.136 - pyansibleinv - dbbackup_mysql_disable_stderr - ERROR - obj, end = self.raw_decode(s, idx=_w(s, 0).end())
2018-04-24 15:37:09.137 - pyansibleinv - dbbackup_mysql_disable_stderr - ERROR -   File "/usr/lib64/python2.7/json/decoder.py", line 384, in raw_decode
2018-04-24 15:37:09.137 - pyansibleinv - dbbackup_mysql_disable_stderr - ERROR - raise ValueError("No JSON object could be decoded")
2018-04-24 15:37:09.137 - pyansibleinv - dbbackup_mysql_disable_stderr - ERROR - ValueError
2018-04-24 15:37:09.137 - pyansibleinv - dbbackup_mysql_disable_stderr - ERROR - :
2018-04-24 15:37:09.137 - pyansibleinv - dbbackup_mysql_disable_stderr - ERROR - No JSON object could be decoded
