2018-04-24 15:05:16.993 - pyansibleinv -        dbbackup_mysql_list -  INFO - args:{'--cluster_id': None,
 '--data_host': 'dcs-db-c00aee9f.iad1:10.41.234.57',
 '--dbfqdn': 'dcs-db-c00aee9f.iad1',
 '--dbtype': 'mysql',
 '--ssh_try_limit': '600',
 '--sshkey': '/opt/ansible/db.pem',
 '--sshpass': 'LR1!Ika',
 '--taskid': None,
 '--template_only': False,
 '--workdir': '/opt/ansible',
 'dbbackup': True,
 'debug': False,
 'list': True}
2018-04-24 15:05:16.993 - pyansibleinv -        dbbackup_mysql_list -  INFO - dict:{'ssh_try_limit': '600', 'workdir': '/opt/ansible', 'sshkey': '/opt/ansible/db.pem', 'template_only': False, 'dbtype': 'mysql', 'backup': True, 'taskid': None, 'task_id': '  external_task_id: 93ee03b2-7254-4670-9914-ad2a22363ff0\n', 'st': True, 'cluster_id': None, 'sshpass': 'LR1!Ika', 'dbfqdn': 'dcs-db-c00aee9f.iad1', 'data_host': 'dcs-db-c00aee9f.iad1:10.41.234.57', 'bug': False, 'uuid': '93ee03b2-7254-4670-9914-ad2a22363ff0'}
2018-04-24 15:05:16.993 - pyansibleinv -        dbbackup_mysql_list -  INFO - create ansible hosts: /opt/ansible/inventory/93ee03b2-7254-4670-9914-ad2a22363ff0/hosts
2018-04-24 15:05:16.994 - pyansibleinv -        dbbackup_mysql_list -  INFO - craete ansible playbooks: /opt/ansible/dbbackup_mysql_list_93ee03b2-7254-4670-9914-ad2a22363ff0.yml
2018-04-24 15:05:16.996 - pyansibleinv -        dbbackup_mysql_list -  INFO - check ssh availability
2018-04-24 15:05:16.996 - pyansibleinv - dbbackup_mysql_list_stdout -  INFO - Attempting to connect to 10.41.234.57 on port 22
2018-04-24 15:05:17.064 - pyansibleinv - dbbackup_mysql_list_stdout -  INFO - Connected to 10.41.234.57 on port 22
2018-04-24 15:05:17.064 - pyansibleinv - dbbackup_mysql_list_stdout -  INFO - Attempting to connect to 10.41.234.57 on port 22
2018-04-24 15:05:17.132 - pyansibleinv - dbbackup_mysql_list_stdout -  INFO - Connected to 10.41.234.57 on port 22
2018-04-24 15:05:17.132 - pyansibleinv -        dbbackup_mysql_list -  INFO - run ansible from python
2018-04-24 15:05:17.739 - pyansibleinv - dbbackup_mysql_list_stdout -  INFO - 
2018-04-24 15:05:17.739 - pyansibleinv - dbbackup_mysql_list_stdout -  INFO - PLAY [list backup sets] ***********************************************************************************************************************************************************************
2018-04-24 15:05:18.498 - pyansibleinv - dbbackup_mysql_list_stdout -  INFO - 
2018-04-24 15:05:18.498 - pyansibleinv - dbbackup_mysql_list_stdout -  INFO - TASK [list mysql backup set] ******************************************************************************************************************************************************************
2018-04-24 15:05:21.478 - pyansibleinv - dbbackup_mysql_list_stdout -  INFO - [0;33mchanged: [dcs-db-c00aee9f.iad1][0m
2018-04-24 15:05:22.184 - pyansibleinv - dbbackup_mysql_list_stdout -  INFO - 
2018-04-24 15:05:22.184 - pyansibleinv - dbbackup_mysql_list_stdout -  INFO - TASK [Record backup result] *******************************************************************************************************************************************************************
2018-04-24 15:05:22.423 - pyansibleinv - dbbackup_mysql_list_stdout -  INFO - [0;32mok: [dcs-db-c00aee9f.iad1][0m
2018-04-24 15:05:22.444 - pyansibleinv - dbbackup_mysql_list_stdout -  INFO - 
2018-04-24 15:05:22.444 - pyansibleinv - dbbackup_mysql_list_stdout -  INFO - PLAY RECAP ************************************************************************************************************************************************************************************
2018-04-24 15:05:22.444 - pyansibleinv - dbbackup_mysql_list_stdout -  INFO - [0;33mdcs-db-c00aee9f.iad1[0m       : [0;32mok=2   [0m [0;33mchanged=1   [0m unreachable=0    failed=0
2018-04-24 15:05:22.483 - pyansibleinv - dbbackup_mysql_list_stdout -  INFO - --- Total Excution time: 0:00:05.490955 ---
2018-04-24 15:05:22.499 - pyansibleinv - dbbackup_mysql_list_stderr - ERROR - Traceback (most recent call last):
2018-04-24 15:05:22.499 - pyansibleinv - dbbackup_mysql_list_stderr - ERROR -   File "/usr/bin/pyansibleinv", line 11, in <module>
2018-04-24 15:05:22.500 - pyansibleinv - dbbackup_mysql_list_stderr - ERROR - load_entry_point('pyansibleinv==0.1.0', 'console_scripts', 'pyansibleinv')()
2018-04-24 15:05:22.500 - pyansibleinv - dbbackup_mysql_list_stderr - ERROR -   File "/usr/lib/python2.7/site-packages/pyansibleinv/pyansibleinv.py", line 34, in main
2018-04-24 15:05:22.500 - pyansibleinv - dbbackup_mysql_list_stderr - ERROR - return getattr(module_script, func)(module_args)
2018-04-24 15:05:22.500 - pyansibleinv - dbbackup_mysql_list_stderr - ERROR -   File "/usr/lib/python2.7/site-packages/pyansibleinv/inv_module/dbbackup.py", line 138, in list
2018-04-24 15:05:22.500 - pyansibleinv - dbbackup_mysql_list_stderr - ERROR - cmd = 'data show --playbook %s mybak_%s -f json --debug' % (backup_dict['uuid'], host_info)
2018-04-24 15:05:22.500 - pyansibleinv - dbbackup_mysql_list_stderr - ERROR - NameError
2018-04-24 15:05:22.500 - pyansibleinv - dbbackup_mysql_list_stderr - ERROR - :
2018-04-24 15:05:22.501 - pyansibleinv - dbbackup_mysql_list_stderr - ERROR - global name 'backup_dict' is not defined
